<?xml version="1.0" encoding="UTF-8"?>
<!-- Generated by org.testng.reporters.JUnitReportReporter -->
<testsuite hostname="PT269LT" failures="2" tests="19" name="newweb.vectorfile2" time="29.377" errors="0" timestamp="2024-06-07T16:05:21 IST" skipped="0">
  <testcase classname="newweb.vectorfile2" name="waitForOrderToBeOutForDelivery" time="2.068"/>
  <system-out/>
  <testcase classname="newweb.vectorfile2" name="checkReturnRequestConfirmationEmail" time="1.576"/>
  <system-out/>
  <testcase classname="newweb.vectorfile2" name="navigateToHeaderSection" time="1.676"/>
  <system-out/>
  <testcase classname="newweb.vectorfile2" name="placeOrderAndReceiveConfirmationEmail" time="1.377"/>
  <system-out/>
  <testcase classname="newweb.vectorfile2" name="locateHelpCenterLink" time="1.534"/>
  <system-out/>
  <testcase classname="newweb.vectorfile2" name="cancelUnshippedOrder" time="1.515">
    <failure message="There should be at least one unshipped order expected [false] but found [true]" type="java.lang.AssertionError">
      <![CDATA[java.lang.AssertionError: There should be at least one unshipped order expected [false] but found [true]
at org.testng.Assert.fail(Assert.java:99)
at org.testng.Assert.failNotEquals(Assert.java:1037)
at org.testng.Assert.assertFalse(Assert.java:67)
at newweb.vectorfile2.cancelUnshippedOrder(vectorfile2.java:702)
at java.base/jdk.internal.reflect.NativeMethodAccessorImpl.invoke0(Native Method)
at java.base/jdk.internal.reflect.NativeMethodAccessorImpl.invoke(NativeMethodAccessorImpl.java:77)
at java.base/jdk.internal.reflect.DelegatingMethodAccessorImpl.invoke(DelegatingMethodAccessorImpl.java:43)
at java.base/java.lang.reflect.Method.invoke(Method.java:568)
at org.testng.internal.MethodInvocationHelper.invokeMethod(MethodInvocationHelper.java:133)
at org.testng.internal.TestInvoker.invokeMethod(TestInvoker.java:598)
at org.testng.internal.TestInvoker.invokeTestMethod(TestInvoker.java:173)
at org.testng.internal.MethodRunner.runInSequence(MethodRunner.java:46)
at org.testng.internal.TestInvoker$MethodInvocationAgent.invoke(TestInvoker.java:824)
at org.testng.internal.TestInvoker.invokeTestMethods(TestInvoker.java:146)
at org.testng.internal.TestMethodWorker.invokeTestMethods(TestMethodWorker.java:146)
at org.testng.internal.TestMethodWorker.run(TestMethodWorker.java:128)
at java.base/java.util.ArrayList.forEach(ArrayList.java:1511)
at org.testng.TestRunner.privateRun(TestRunner.java:794)
at org.testng.TestRunner.run(TestRunner.java:596)
at org.testng.SuiteRunner.runTest(SuiteRunner.java:377)
at org.testng.SuiteRunner.runSequentially(SuiteRunner.java:371)
at org.testng.SuiteRunner.privateRun(SuiteRunner.java:332)
at org.testng.SuiteRunner.run(SuiteRunner.java:276)
at org.testng.SuiteRunnerWorker.runSuite(SuiteRunnerWorker.java:53)
at org.testng.SuiteRunnerWorker.run(SuiteRunnerWorker.java:96)
at org.testng.TestNG.runSuitesSequentially(TestNG.java:1212)
at org.testng.TestNG.runSuitesLocally(TestNG.java:1134)
at org.testng.TestNG.runSuites(TestNG.java:1063)
at org.testng.TestNG.run(TestNG.java:1031)
at org.testng.remote.AbstractRemoteTestNG.run(AbstractRemoteTestNG.java:115)
at org.testng.remote.RemoteTestNG.initAndRun(RemoteTestNG.java:251)
at org.testng.remote.RemoteTestNG.main(RemoteTestNG.java:77)
]]>
    </failure>
  </testcase> <!-- cancelUnshippedOrder -->
  <system-out/>
  <testcase classname="newweb.vectorfile2" name="initiateReturnRequest" time="1.503"/>
  <system-out/>
  <testcase classname="newweb.vectorfile2" name="receiveConfirmationEmailForCancellations" time="1.536"/>
  <system-out/>
  <testcase classname="newweb.vectorfile2" name="verifyHelpCenterContent" time="1.514"/>
  <system-out/>
  <testcase classname="newweb.vectorfile2" name="checkHelpCenterLinkInFooter" time="1.488"/>
  <system-out/>
  <testcase classname="newweb.vectorfile2" name="reviewReturnConfirmationEmailContent" time="1.343">
    <failure message="The email should contain detailed next steps for the return process expected [true] but found [false]" type="java.lang.AssertionError">
      <![CDATA[java.lang.AssertionError: The email should contain detailed next steps for the return process expected [true] but found [false]
at org.testng.Assert.fail(Assert.java:99)
at org.testng.Assert.failNotEquals(Assert.java:1037)
at org.testng.Assert.assertTrue(Assert.java:45)
at newweb.vectorfile2.reviewReturnConfirmationEmailContent(vectorfile2.java:571)
at java.base/jdk.internal.reflect.NativeMethodAccessorImpl.invoke0(Native Method)
at java.base/jdk.internal.reflect.NativeMethodAccessorImpl.invoke(NativeMethodAccessorImpl.java:77)
at java.base/jdk.internal.reflect.DelegatingMethodAccessorImpl.invoke(DelegatingMethodAccessorImpl.java:43)
at java.base/java.lang.reflect.Method.invoke(Method.java:568)
at org.testng.internal.MethodInvocationHelper.invokeMethod(MethodInvocationHelper.java:133)
at org.testng.internal.TestInvoker.invokeMethod(TestInvoker.java:598)
at org.testng.internal.TestInvoker.invokeTestMethod(TestInvoker.java:173)
at org.testng.internal.MethodRunner.runInSequence(MethodRunner.java:46)
at org.testng.internal.TestInvoker$MethodInvocationAgent.invoke(TestInvoker.java:824)
at org.testng.internal.TestInvoker.invokeTestMethods(TestInvoker.java:146)
at org.testng.internal.TestMethodWorker.invokeTestMethods(TestMethodWorker.java:146)
at org.testng.internal.TestMethodWorker.run(TestMethodWorker.java:128)
at java.base/java.util.ArrayList.forEach(ArrayList.java:1511)
at org.testng.TestRunner.privateRun(TestRunner.java:794)
at org.testng.TestRunner.run(TestRunner.java:596)
at org.testng.SuiteRunner.runTest(SuiteRunner.java:377)
at org.testng.SuiteRunner.runSequentially(SuiteRunner.java:371)
at org.testng.SuiteRunner.privateRun(SuiteRunner.java:332)
at org.testng.SuiteRunner.run(SuiteRunner.java:276)
at org.testng.SuiteRunnerWorker.runSuite(SuiteRunnerWorker.java:53)
at org.testng.SuiteRunnerWorker.run(SuiteRunnerWorker.java:96)
at org.testng.TestNG.runSuitesSequentially(TestNG.java:1212)
at org.testng.TestNG.runSuitesLocally(TestNG.java:1134)
at org.testng.TestNG.runSuites(TestNG.java:1063)
at org.testng.TestNG.run(TestNG.java:1031)
at org.testng.remote.AbstractRemoteTestNG.run(AbstractRemoteTestNG.java:115)
at org.testng.remote.RemoteTestNG.initAndRun(RemoteTestNG.java:251)
at org.testng.remote.RemoteTestNG.main(RemoteTestNG.java:77)
]]>
    </failure>
  </testcase> <!-- reviewReturnConfirmationEmailContent -->
  <system-out/>
  <testcase classname="newweb.vectorfile2" name="waitForOrderToBeProcessedAndShipped" time="1.469"/>
  <system-out/>
  <testcase classname="newweb.vectorfile2" name="locateFooterSection" time="1.579"/>
  <system-out/>
  <testcase classname="newweb.vectorfile2" name="navigateToOrderHistory" time="1.509"/>
  <system-out/>
  <testcase classname="newweb.vectorfile2" name="accessHelpCenterFromAnyPage" time="1.379"/>
  <system-out/>
  <testcase classname="newweb.vectorfile2" name="checkHelpCenterLinkInHeader" time="1.495"/>
  <system-out/>
  <testcase classname="newweb.vectorfile2" name="accessHelpCenterPage" time="1.527"/>
  <system-out/>
  <testcase classname="newweb.vectorfile2" name="receiveConfirmationEmailForReturns" time="1.490"/>
  <system-out/>
  <testcase classname="newweb.vectorfile2" name="verifyHelpCenterContentSections" time="1.799"/>
  <system-out/>
</testsuite> <!-- newweb.vectorfile2 -->
